<?xml version="1.0" ?>
<sdf version="1.5">
  <model name="hri_robot">

    <link name="chassis">
      <pose>0 0 0.16 0 0 0</pose>
      <inertial>
	
        <mass>5.67</mass>
        <inertia>
          <ixx>0.07</ixx>
          <iyy>0.08</iyy>
          <izz>0.10</izz>
          <ixy>0</ixy>
          <ixz>0</ixz>
          <iyz>0</iyz>
        </inertia>
      </inertial>
      
      <collision name="collision">
        <geometry>
          <box>
            <size>0.445 0.277 0.17</size>
          </box>
        </geometry>
      </collision>
      <collision name="castor_collision">
        <pose>-0.200 0 -0.12 0 0 0</pose>
        <geometry>
          <sphere>
            <radius>0.04</radius>
          </sphere>
        </geometry>
        <surface>
          <friction>
            <ode>
              <mu>0</mu>
              <mu2>0</mu2>
              <slip1>1.0</slip1>
              <slip2>1.0</slip2>
            </ode>
          </friction>
        </surface>
      </collision>
      <collision name="castor_collision2">
        <pose>0.200 0 -0.12 0 0 0</pose>
        <geometry>
          <sphere>
            <radius>0.04</radius>
          </sphere>
        </geometry>
        <surface>
          <friction>
            <ode>
              <mu>0</mu>
              <mu2>0</mu2>
              <slip1>1.0</slip1>
              <slip2>1.0</slip2>
            </ode>
          </friction>
        </surface>
      </collision>
      <visual name="visual">
        <pose>0 0 0.04 0 0 0</pose>
        <geometry>
          <mesh>
            <uri>model://hri_robot/meshes/chassis.dae</uri>
          </mesh>
        </geometry>
      </visual>
      <visual name="castor_visual">
        <pose>-0.200 0 -0.12 0 0 0</pose>
        <geometry>
          <sphere>
            <radius>0.04</radius>
          </sphere>
        </geometry>
        <material>
          <script>
            <uri>file://media/materials/scripts/gazebo.material</uri>
            <name>Gazebo/FlatBlack</name>
          </script>
        </material>
      </visual>
      <visual name="castor_visual2">
        <pose>0.200 0 -0.12 0 0 0</pose>
        <geometry>
          <sphere>
            <radius>0.04</radius>
          </sphere>
        </geometry>
        <material>
          <script>
            <uri>file://media/materials/scripts/gazebo.material</uri>
            <name>Gazebo/FlatBlack</name>
          </script>
        </material>
      </visual>
    </link>  
    
    <link name = "frame">
      <pose>0 0 0.16 0 0 0</pose>
      <inertial>
	
        <mass>5.67</mass>
        <inertia>
          <ixx>0.07</ixx>
          <iyy>0.08</iyy>
          <izz>0.10</izz>
          <ixy>0</ixy>
          <ixz>0</ixz>
          <iyz>0</iyz>
        </inertia>
      </inertial>
    
      <collision name="collision1">
	<pose>-0.05 0 0.485 0 0 0</pose>
        <geometry>
          <box>
            <size>0.05 0.05 0.80</size>
          </box>
        </geometry>
      </collision>
      <visual name="visual1">
	<pose>-0.05 0 0.485 0 0 0</pose>
        <geometry>
          <box>
            <size>0.05 0.05 0.80</size>
          </box>
        </geometry>
      </visual>

      <collision name="collision2">
	<pose>0 0 0.885 0 0 0</pose>
        <geometry>
          <box>
            <size>0.20 0.05 0.01</size>
          </box>
        </geometry>
      </collision>
      <visual name="visual2">
	<pose>0 0 0.885 0 0 0</pose>
        <geometry>
          <box>
            <size>0.20 0.05 0.01</size>
          </box>
        </geometry>
      </visual>

      <collision name="collision3">
	<pose>0.10 0 0.4 0 0 0</pose>
        <geometry>
          <box>
            <size>0.30 0.30 0.01</size>
          </box>
        </geometry>
      </collision>
      <visual name="visual3">
	<pose>0.10 0 0.4 0 0 0</pose>
        <geometry>
          <box>
            <size>0.30 0.30 0.01</size>
          </box>
        </geometry>
      </visual>
      
    </link>

    <link name="right_wheel">
      <pose>0.1 -.17 0.11 0 1.5707 1.5707</pose>
      <inertial>
        <mass>1.5</mass>
        <inertia>
          <ixx>0.0051</ixx>
          <iyy>0.0051</iyy>
          <izz>0.0090</izz>
          <ixy>0</ixy>
          <ixz>0</ixz>
          <iyz>0</iyz>
        </inertia>
      </inertial>
      <collision name="collision">
        <geometry>
          <cylinder>
            <radius>0.11</radius>
            <length>0.05</length>
          </cylinder>
        </geometry>
        <surface>
          <friction>
            <ode>
              <mu>100000.0</mu>
              <mu2>100000.0</mu2>
              <slip1>0.0</slip1>
              <slip2>0.0</slip2>
            </ode>
          </friction>
        </surface>
      </collision>
      <visual name="visual">
        <geometry>
          <cylinder>
            <radius>0.11</radius>
            <length>0.05</length>
          </cylinder>
        </geometry>
        <material>
          <script>
            <uri>file://media/materials/scripts/gazebo.material</uri>
            <name>Gazebo/FlatBlack</name>
          </script>
        </material>
      </visual>
    </link>
    
    <joint type="fixed" name="frame_connector">     
      <pose>0 0 0.50 0 0 0</pose>
      <child>frame</child>
      <parent>chassis</parent>
      <axis>
        <xyz>0 1 0</xyz>
        <limit>
          <upper>1</upper>
          <lower>-1</lower>
        </limit>
	<dynamics>
          <damping>1.000000</damping>
          <friction>0.000000</friction>
        </dynamics>
      </axis>
      <use_parent_model_frame>true</use_parent_model_frame>
    </joint>

    <link name="left_wheel">
      <pose>0.1 .17 0.11 0 1.5707 1.5707</pose>
      <inertial>
        <mass>1.5</mass>
        <inertia>
          <ixx>0.0051</ixx>
          <iyy>0.0051</iyy>
          <izz>0.0090</izz>
          <ixy>0</ixy>
          <ixz>0</ixz>
          <iyz>0</iyz>
        </inertia>
      </inertial>
      <collision name="collision">
        <geometry>
          <cylinder>
            <radius>0.11</radius>
            <length>0.05</length>
          </cylinder>
        </geometry>
        <surface>
          <friction>
            <ode>
              <mu>100000.0</mu>
              <mu2>100000.0</mu2>
              <slip1>0.0</slip1>
              <slip2>0.0</slip2>
            </ode>
          </friction>
        </surface>
      </collision>
      <visual name="visual">
        <geometry>
          <cylinder>
            <radius>0.11</radius>
            <length>0.05</length>
          </cylinder>
        </geometry>
        <material>
          <script>
            <uri>file://media/materials/scripts/gazebo.material</uri>
            <name>Gazebo/FlatBlack</name>
          </script>
        </material>
      </visual>
    </link>

    <joint type="revolute" name="left_wheel_hinge">
      <pose>0 0 -0.03 0 0 0</pose>
      <child>left_wheel</child>
      <parent>chassis</parent>
      <axis>
        <xyz>0 1 0</xyz>
        <use_parent_model_frame>true</use_parent_model_frame>
      </axis>
    </joint>

    <joint type="revolute" name="right_wheel_hinge">
      <pose>0 0 0.03 0 0 0</pose>
      <child>right_wheel</child>
      <parent>chassis</parent>
      <axis>
        <xyz>0 1 0</xyz>
        <use_parent_model_frame>true</use_parent_model_frame>
      </axis>
    </joint>



    <plugin name="differential_drive_controller" filename="libgazebo_ros_diff_drive.so">
	<alwaysOn>true</alwaysOn>
	<updateRate>100</updateRate>
	<leftJoint>left_wheel_hinge</leftJoint>
	<rightJoint>right_wheel_hinge</rightJoint>
	<wheelSeparation>0.44</wheelSeparation>
	<wheelDiameter>0.22</wheelDiameter>
	<wheelTorque>5.0</wheelTorque>
	<commandTopic>cmd_vel</commandTopic>
	<odometryTopic>odom</odometryTopic>
	<odometryFrame>odom</odometryFrame>
	<robotBaseFrame>base_footprint</robotBaseFrame>
    </plugin>

    <include>
      <uri>model://kinect</uri>
      <pose>0.15 0 1.10 0 0 0</pose>
    </include>
    <joint type="revolute" name="kinect_joint">     
      <pose>0 0 0 0 0 0</pose>
      <child>kinect::link</child>
      <parent>chassis</parent>
      <axis>
        <xyz>0 1 0</xyz>
        <limit>
          <upper>1</upper>
          <lower>-1</lower>
        </limit>
	<dynamics>
          <damping>1.000000</damping>
          <friction>0.000000</friction>
        </dynamics>
      </axis>
      <use_parent_model_frame>true</use_parent_model_frame>
    </joint>
    
    <plugin name="kinect_tilt_controller" filename="libhri_gazebo_platform_kinect_tilt_plugin.so">
      <tiltJoint>kinect_joint</tiltJoint>
    </plugin>
    
  </model>
</sdf>
